# Промисы: обработка ошибок
Вокруг функции промиса и обработчиков находится "невидимый ```try..catch```". Если происходит исключение, то оно перехватывается, 
и промис считается отклонённым с этой ошибкой.
Блок ```catch``` перехватывает только синхронные ошибки.

## Примеры обработки ошибок в промисах с помощью catch:

Если в любом блоке ```then``` произойдет ошибка, то все последующие ```then``` будут проигнорированы, ошибка будет перехвачена и сработает блок ```catch```

```
fetch('/article/promise-chaining/user.json')
  .then(response => response.json())
  .then(user => fetch(`https://api.github.com/users/${user.name}`))
  .then(response => response.json())
  .then(githubUser => new Promise((resolve, reject) => {
     //CODE   
  }))
  .catch(error => alert(error.message));
```

catch можно ставить в любом порядке и в любом количестве, а не только в конце цепочки, 
если ошибка не обработана в текущем блоке ```catch```, то ее можно пробросить дальше, в таком
случае следующие блоки ```then``` будут проигнорированы до следующего блока ```catch```:

```
new Promise((resolve, reject) => {

  throw new Error("Ошибка!");

}).catch(function(error) {

  if (error instanceof URIError) {
  
    // обрабатываем ошибку
    
  } else {
  
    alert("Не могу обработать ошибку");
    throw error; // пробрасывает эту или другую ошибку в следующий catch
    
  }

}).then(function() {

  /* не выполнится */
  
}).catch(error => {

  alert(`Неизвестная ошибка: ${error}`);
  // ничего не возвращаем => выполнение продолжается в нормальном режиме

});
```